Traceback (most recent call last):
  File "/home1/yzw/ENTER/envs/intern_clean/lib/python3.9/site-packages/huggingface_hub/utils/_http.py", line 409, in hf_raise_for_status
    response.raise_for_status()
  File "/home1/yzw/ENTER/envs/intern_clean/lib/python3.9/site-packages/requests/models.py", line 1024, in raise_for_status
    raise HTTPError(http_error_msg, response=self)
requests.exceptions.HTTPError: 404 Client Error: Not Found for url: https://hf-mirror.com/mistral-7B/resolve/main/tokenizer_config.json

The above exception was the direct cause of the following exception:

Traceback (most recent call last):
  File "/home1/yzw/ENTER/envs/intern_clean/lib/python3.9/site-packages/transformers/utils/hub.py", line 424, in cached_files
    hf_hub_download(
  File "/home1/yzw/ENTER/envs/intern_clean/lib/python3.9/site-packages/huggingface_hub/utils/_validators.py", line 114, in _inner_fn
    return fn(*args, **kwargs)
  File "/home1/yzw/ENTER/envs/intern_clean/lib/python3.9/site-packages/huggingface_hub/file_download.py", line 961, in hf_hub_download
    return _hf_hub_download_to_cache_dir(
  File "/home1/yzw/ENTER/envs/intern_clean/lib/python3.9/site-packages/huggingface_hub/file_download.py", line 1068, in _hf_hub_download_to_cache_dir
    _raise_on_head_call_error(head_call_error, force_download, local_files_only)
  File "/home1/yzw/ENTER/envs/intern_clean/lib/python3.9/site-packages/huggingface_hub/file_download.py", line 1596, in _raise_on_head_call_error
    raise head_call_error
  File "/home1/yzw/ENTER/envs/intern_clean/lib/python3.9/site-packages/huggingface_hub/file_download.py", line 1484, in _get_metadata_or_catch_error
    metadata = get_hf_file_metadata(
  File "/home1/yzw/ENTER/envs/intern_clean/lib/python3.9/site-packages/huggingface_hub/utils/_validators.py", line 114, in _inner_fn
    return fn(*args, **kwargs)
  File "/home1/yzw/ENTER/envs/intern_clean/lib/python3.9/site-packages/huggingface_hub/file_download.py", line 1401, in get_hf_file_metadata
    r = _request_wrapper(
  File "/home1/yzw/ENTER/envs/intern_clean/lib/python3.9/site-packages/huggingface_hub/file_download.py", line 285, in _request_wrapper
    response = _request_wrapper(
  File "/home1/yzw/ENTER/envs/intern_clean/lib/python3.9/site-packages/huggingface_hub/file_download.py", line 309, in _request_wrapper
    hf_raise_for_status(response)
  File "/home1/yzw/ENTER/envs/intern_clean/lib/python3.9/site-packages/huggingface_hub/utils/_http.py", line 459, in hf_raise_for_status
    raise _format(RepositoryNotFoundError, message, response) from e
huggingface_hub.errors.RepositoryNotFoundError: 404 Client Error. (Request ID: Root=1-67f599c7-6b385f4b70d0f1ac4e21403a;abd19440-9521-484d-92ea-2e517333a4d6)

Repository Not Found for url: https://hf-mirror.com/mistral-7B/resolve/main/tokenizer_config.json.
Please make sure you specified the correct `repo_id` and `repo_type`.
If you are trying to access a private or gated repo, make sure you are authenticated. For more details, see https://huggingface.co/docs/huggingface_hub/authentication

The above exception was the direct cause of the following exception:

Traceback (most recent call last):
  File "/home1/yzw/rewardModel/Mistral_7b/train.py", line 188, in <module>
    main(args)
  File "/home1/yzw/rewardModel/Mistral_7b/train.py", line 61, in main
    tokenizer = AutoTokenizer.from_pretrained(args.model_name, use_fast=False)
  File "/home1/yzw/ENTER/envs/intern_clean/lib/python3.9/site-packages/transformers/models/auto/tokenization_auto.py", line 910, in from_pretrained
    tokenizer_config = get_tokenizer_config(pretrained_model_name_or_path, **kwargs)
  File "/home1/yzw/ENTER/envs/intern_clean/lib/python3.9/site-packages/transformers/models/auto/tokenization_auto.py", line 742, in get_tokenizer_config
    resolved_config_file = cached_file(
  File "/home1/yzw/ENTER/envs/intern_clean/lib/python3.9/site-packages/transformers/utils/hub.py", line 266, in cached_file
    file = cached_files(path_or_repo_id=path_or_repo_id, filenames=[filename], **kwargs)
  File "/home1/yzw/ENTER/envs/intern_clean/lib/python3.9/site-packages/transformers/utils/hub.py", line 456, in cached_files
    raise EnvironmentError(
OSError: mistral-7B is not a local folder and is not a valid model identifier listed on 'https://huggingface.co/models'
If this is a private repository, make sure to pass a token having permission to this repo either by logging in with `huggingface-cli login` or by passing `token=<your_token>`
[rank0]: Traceback (most recent call last):
[rank0]:   File "/home1/yzw/ENTER/envs/intern_clean/lib/python3.9/site-packages/huggingface_hub/utils/_http.py", line 409, in hf_raise_for_status
[rank0]:     response.raise_for_status()
[rank0]:   File "/home1/yzw/ENTER/envs/intern_clean/lib/python3.9/site-packages/requests/models.py", line 1024, in raise_for_status
[rank0]:     raise HTTPError(http_error_msg, response=self)
[rank0]: requests.exceptions.HTTPError: 404 Client Error: Not Found for url: https://hf-mirror.com/mistral-7B/resolve/main/tokenizer_config.json

[rank0]: The above exception was the direct cause of the following exception:

[rank0]: Traceback (most recent call last):
[rank0]:   File "/home1/yzw/ENTER/envs/intern_clean/lib/python3.9/site-packages/transformers/utils/hub.py", line 424, in cached_files
[rank0]:     hf_hub_download(
[rank0]:   File "/home1/yzw/ENTER/envs/intern_clean/lib/python3.9/site-packages/huggingface_hub/utils/_validators.py", line 114, in _inner_fn
[rank0]:     return fn(*args, **kwargs)
[rank0]:   File "/home1/yzw/ENTER/envs/intern_clean/lib/python3.9/site-packages/huggingface_hub/file_download.py", line 961, in hf_hub_download
[rank0]:     return _hf_hub_download_to_cache_dir(
[rank0]:   File "/home1/yzw/ENTER/envs/intern_clean/lib/python3.9/site-packages/huggingface_hub/file_download.py", line 1068, in _hf_hub_download_to_cache_dir
[rank0]:     _raise_on_head_call_error(head_call_error, force_download, local_files_only)
[rank0]:   File "/home1/yzw/ENTER/envs/intern_clean/lib/python3.9/site-packages/huggingface_hub/file_download.py", line 1596, in _raise_on_head_call_error
[rank0]:     raise head_call_error
[rank0]:   File "/home1/yzw/ENTER/envs/intern_clean/lib/python3.9/site-packages/huggingface_hub/file_download.py", line 1484, in _get_metadata_or_catch_error
[rank0]:     metadata = get_hf_file_metadata(
[rank0]:   File "/home1/yzw/ENTER/envs/intern_clean/lib/python3.9/site-packages/huggingface_hub/utils/_validators.py", line 114, in _inner_fn
[rank0]:     return fn(*args, **kwargs)
[rank0]:   File "/home1/yzw/ENTER/envs/intern_clean/lib/python3.9/site-packages/huggingface_hub/file_download.py", line 1401, in get_hf_file_metadata
[rank0]:     r = _request_wrapper(
[rank0]:   File "/home1/yzw/ENTER/envs/intern_clean/lib/python3.9/site-packages/huggingface_hub/file_download.py", line 285, in _request_wrapper
[rank0]:     response = _request_wrapper(
[rank0]:   File "/home1/yzw/ENTER/envs/intern_clean/lib/python3.9/site-packages/huggingface_hub/file_download.py", line 309, in _request_wrapper
[rank0]:     hf_raise_for_status(response)
[rank0]:   File "/home1/yzw/ENTER/envs/intern_clean/lib/python3.9/site-packages/huggingface_hub/utils/_http.py", line 459, in hf_raise_for_status
[rank0]:     raise _format(RepositoryNotFoundError, message, response) from e
[rank0]: huggingface_hub.errors.RepositoryNotFoundError: 404 Client Error. (Request ID: Root=1-67f599c7-6b385f4b70d0f1ac4e21403a;abd19440-9521-484d-92ea-2e517333a4d6)

[rank0]: Repository Not Found for url: https://hf-mirror.com/mistral-7B/resolve/main/tokenizer_config.json.
[rank0]: Please make sure you specified the correct `repo_id` and `repo_type`.
[rank0]: If you are trying to access a private or gated repo, make sure you are authenticated. For more details, see https://huggingface.co/docs/huggingface_hub/authentication

[rank0]: The above exception was the direct cause of the following exception:

[rank0]: Traceback (most recent call last):
[rank0]:   File "/home1/yzw/rewardModel/Mistral_7b/train.py", line 188, in <module>
[rank0]:     main(args)
[rank0]:   File "/home1/yzw/rewardModel/Mistral_7b/train.py", line 61, in main
[rank0]:     tokenizer = AutoTokenizer.from_pretrained(args.model_name, use_fast=False)
[rank0]:   File "/home1/yzw/ENTER/envs/intern_clean/lib/python3.9/site-packages/transformers/models/auto/tokenization_auto.py", line 910, in from_pretrained
[rank0]:     tokenizer_config = get_tokenizer_config(pretrained_model_name_or_path, **kwargs)
[rank0]:   File "/home1/yzw/ENTER/envs/intern_clean/lib/python3.9/site-packages/transformers/models/auto/tokenization_auto.py", line 742, in get_tokenizer_config
[rank0]:     resolved_config_file = cached_file(
[rank0]:   File "/home1/yzw/ENTER/envs/intern_clean/lib/python3.9/site-packages/transformers/utils/hub.py", line 266, in cached_file
[rank0]:     file = cached_files(path_or_repo_id=path_or_repo_id, filenames=[filename], **kwargs)
[rank0]:   File "/home1/yzw/ENTER/envs/intern_clean/lib/python3.9/site-packages/transformers/utils/hub.py", line 456, in cached_files
[rank0]:     raise EnvironmentError(
[rank0]: OSError: mistral-7B is not a local folder and is not a valid model identifier listed on 'https://huggingface.co/models'
[rank0]: If this is a private repository, make sure to pass a token having permission to this repo either by logging in with `huggingface-cli login` or by passing `token=<your_token>`
